Workbook

Sheet Productos-precio
B1: Producto | C1: Cantidad | D1: Precio | G1: Producto | H1: Cantidad | I1: Precio unitario | J1: Total precio
B2: Absenta Pernod (ÁLVAREZ) | D2: 27.91
B3: Absenta Pernod (LAFUENTE) | D3: 24.84 | G3: Naranjas | H3: 1kg | I3: 1.1
B4: Absenta Hencdricks | D4: 30.8 | G4: Limones | H4: 1kg | I4: 1.1
G5: Limas | H5: 1kg | I5: 2.95
B6: Agua perrier | D6: 1.013 | G6: Z. Limón | H6: 1L | I6: 3.95
B7: Agua Solan | D7: 0.7 | G7: Jengibre | H7: 1kg | I7: 6.95
G8: Hoja de Ostra | H8: 50unds | I8: 19.5
B9: Amaro averna (ÁLVAREZ) | D9: 8.82 | G9: Menta | H9: Manojo | I9: 1.5
B10: Amaro Byrrh | D10: 15 | G10: Azucar Blanco | H10: 1kg | I10: 1.65
B11: Amaro montenegro | D11: 12.6 | G11: Tomate Pelado | H11: 5kg | I11: 6.95
B12: Amaro Montenegro (LAFUENTE) | D12: 13.38 | G12: Mandarina | H12: 1kg | I12: 2.95
B13: Amaro Noix | D13: 21.8 | G13: Aceituna Gordal | H13: 4,5kg | I13: 29.95
B14: Amaro Noix (BARKONSULT) | D14: 21.8 | G14: Melisa | H14: Manojo | I14: 2.5
B15: Amaro Rubarbaro Nardini | D15: 20.3 | G15: Z. Lima | H15: 1L | I15: 12.5
B16: Amaro Sfumato (WKY REGAL) | D16: 11.16 | G16: Clara de Huevo | H16: 1L | I16: 4.95
G17: Miel | H17: 1kg | I17: 9.95
B18: Aperitivo Lillet Blanc (LAFUENTE) | D18: 10.11 | G18: Panela | H18: 500gr | I18: 1.85
B19: Aperitivo Lillet Blanc (ÁLVAREZ) | D19: 8.95 | G19: Miso Blanco | H19: 1kg | I19: 7.5
B20: Aperitivo Lillet blanc (BORDINO) | D20: 8.48 | G20: Sal | H20: 1kg | I20: 1
B21: Aperitivo Lillet Rouge (LAFUENTE) | D21: 11.24 | G21: LITCHIS | H21: 1KG | I21: 3.95
B22: Aperitivo Lillet Rouge (BORDINO) | D22: 8.48 | G22: Leche | H22: 1L | I22: 2
G23: Leffir de mango | H23: 500ml | I23: 1.62
B24: Armagñac Cles de ducs V.S.O.P | D24: 15.5
B25: Armagñac DARTIGALONGUE RESERVA 2000 | D25: 42.25
B27: Bitter Walnut Fee Brothers (BARKONSULT) | D27: 12.99
B28: Bitter Peychauds | D28: 12.3
B29: Bitter Luxardo Bianco | D29: 9.17
B30: Bitter angostura (LAFUENTE) | D30: 10.58 | G30: Habatonka | H30: 10 | I30: 2 | J30: =H30*I30 -> 20
B31: Bitter Angostura (ÁLVAREZ) | D31: 9.87 | G31: Ras el hanout | H31: 40 | I31: 2.8 | J31: =H31*I31 -> 112
B32: Bitter Angostura (BORDINO) | D32: 9.12 | G32: Curcuma | H32: 40 | I32: 2 | J32: =H32*I32 -> 80
B33: Bitter Burlesque (LAFUENTE) | D33: 18.44 | G33: Tandoori | H33: 50 | I33: 3 | J33: =H33*I33 -> 150
B34: Bitter Cardamomo | D34: 12.91 | G34: Té Chai | H34: 40 | I34: 3 | J34: =H34*I34 -> 120
B35: Bitter de Apio fee brothers | D35: 14.01 | G35: Cardamomo | H35: 100 | I35: 8 | J35: =H35*I35 -> 800
B36: Bitter hellfire habanero | D36: 18.44 | G36: Té Olong | H36: 40 | I36: 3 | J36: =H36*I36 -> 120
B37: Bitter Orange Angostura (LAFUENTE) | D37: 8.68
B38: Bitter Orange Angostura | D38: 7.07 | G38: Eral Grey | H38: 100 | I38: 6 | J38: =H38*I38 -> 600
B39: Bitter scrappy's Cardamomo (LAFUENTE) | D39: 22.86 | G39: Habanero | H39: 30 | I39: 7.5 | J39: =H39*I39 -> 225
B40: Bitter scrapy´s apio | D40: 18.66 | J40: =H40*I40 -> 0
B41: Bitter scrapy´s fire | D41: 19.48 | J41: =H41*I41 -> 0
...

Sheet stock reed hihgball
B2: Producciones | H2: Campari | I2: 50 | J2: 1000 | K2: 10.96 | L2: =(K2*I2)/J2 -> 0.548
H3: citrus soul | I3: 25 | J3: 1000 | K3: 1.99 | L3: =(K3*I3)/J3 -> 0.04975
B4: Producto en botella | C4: Botellas | D4: Garrafas | H4: Cocktails x 1 | I4: =SUM(I2:I3) -> 75 | L4: =SUM(L2:L3) -> 0.59775
H5: Cocktails x botella | I5: =J5/I4 -> 9.3333333 | J5: 700 | L5: =L4*I5 -> 5.579
B6: Caperucita rosa | H6: Botellas de 700 | J6: 700 | L6: =L5*I6 -> 0
B7: Lisa simpson
B8: Champs Elysses
B9: Watermelon Highball
B10: Fuck cocó | H10: Champs Elysses
B11: Shuffle Along | H11: Vodka | I11: 50 | J11: 700 | K11: 12 | L11: =(K11*I11)/J11 -> 0.85714286
B12: Messie Covarrubias | H12: Premix champs | I12: 45 | J12: 700 | K12: 7.29 | L12: =(K12*I12)/J12 -> 0.46864286
B13: Lovo Island Ice Tea | H13: Citrus Soul | I13: 25 | J13: 1000 | K13: 1.99 | L13: =(K13*I13)/J13 -> 0.04975
B14: Lova | H14: Cocktails x 1 | I14: =SUM(I11:I13) -> 120 | L14: =SUM(L11:L13) -> 1.3755357
B15: Cleopatra nº2 | H15: Cocktails x botella | I15: =J15/I14 -> 5.8333333 | J15: 700 | L15: =L14*I15 -> 8.0239583
B16: Mix Ron | H16: Botellas de 700 | I16: =C8 -> 0 | J16: 700 | L16: =L15*I16 -> 0
B17: Citrus Soul
B18: Sirope Fruta Pasion
B19: Licor café | H19: Shuffle Along
B20: Orange Lovo Liquor | H20: Chartreuse verde | I20: 15 | J20: 700 | K20: 20.55 | L20: =(K20*I20)/J20 -> 0.44035714
B21: Sirope Simple | H21: Gin | I21: 50 | J21: 700 | K21: 11 | L21: =(K21*I21)/J21 -> 0.78571429
B22: White neill Ruibarb | H22: Citrus soul | I22: 25 | J22: 1000 | K22: 1.99 | L22: =(K22*I22)/J22 -> 0.04975
B23: Vermouth-Campari | H23: Licor marraschino | I23: 15 | J23: 700 | K23: 12.55 | L23: =(K23*I23)/J23 -> 0.26892857
B24: Naked | H24: Cocktails x 1 | I24: =SUM(I20:I23) -> 105 | L24: =SUM(L20:L23) -> 1.54475
B25: Porn Star | H25: Cocktails x botella | I25: =J25/I24 -> 6.6666667 | J25: 700 | L25: =L24*I25 -> 10.298333
B26: Old Fashioned | H26: Botellas de 700 | I26: =C11 -> 0 | J26: 700 | L26: =L25*I26 -> 0
B27: J&7
H29: Lovo Island Ice Tea
H30: Havana 3 | I30: 10 | J30: 700 | K30: 9.18 | L30: =(K30*I30)/J30 -> 0.13114286
H31: Gin | I31: 10 | J31: 700 | K31: 11 | L31: =(K31*I31)/J31 -> 0.15714286
H32: Vodka | I32: 10 | J32: 700 | K32: 12 | L32: =(K32*I32)/J32 -> 0.17142857
H33: Tequila | I33: 10 | J33: 700 | K33: 18 | L33: =(K33*I33)/J33 -> 0.25714286
C34: Total | D34: =L6+L16+L26+L39+L48+L76+L89+L96+L106+L57+L66+L116 -> 18.359333 | H34: Orange lovo | I34: 10 | J34: 1400 | K34: 27.52 | L34: =(K34*I34)/J34 -> 0.19657143
H35: Citrus soul | I35: 30 | J35: 1000 | K35: 1.99 | L35: =(K35*I35)/J35 -> 0.0597
H36: Sirope simple | I36: 25 | J36: 1000 | K36: 11.26 | L36: =(K36*I36)/J36 -> 0.2815
H37: Cocktails x 1 | I37: =SUM(I30:I36) -> 105 | L37: =SUM(L30:L36) -> 1.2546286
H38: Cocktails x botella | I38: =J38/I37 -> 6.6666667 | J38: 700 | L38: =L37*I38 -> 8.3641905
H39: Botellas de 700 | I39: =C13 -> 0 | J39: 700 | L39: =L38*I39 -> 0
H40: Garrafa 4L | I40: =J40/I37 -> 0 | J40: =D13 -> 0
H42: Lova
H43: Havana 7 | I43: 50 | J43: 700 | K43: 17.38 | L43: =(K43*I43)/J43 -> 1.2414286
...

Sheet Stock lovo
B2: Producto | D2: Precio | E2: Total
B3: ABSENTA
B4: Absenta Pernod (ÁLVAREZ) | C4: O,7 | D4: 27.91 | E4: =C4*D4 -> #VALUE!
B5: Absenta Pernod (LAFUENTE) | D5: 24.84 | E5: =C5*D5 -> 0
B6: Absenta Hencdricks | D6: 32.017 | E6: =C6*D6 -> 0
E7: =C7*D7 -> 0
B8: AGUA
B9: Agua perrier | D9: 1.013 | E9: =C9*D9 -> 0
B10: Agua Fuentsanta | D10: 0.42 | E10: =C10*D10 -> 0
E11: =C11*D11 -> 0
B12: AMAROS
B13: Amaro averna (ÁLVAREZ) | C13: 0.5 | D13: 9.65 | E13: =C13*D13 -> 4.825
B14: Amaro Byrrh | C14: 0.1 | D14: 15 | E14: =C14*D14 -> 1.5
B15: Amaro montenegro (Barkonsult) | D15: 12.94 | E15: =C15*D15 -> 0
B16: Amaro Montenegro (LAFUENTE) | D16: 13.38 | E16: =C16*D16 -> 0
B17: Amaro Noix | C17: 0.8 | D17: 24 | E17: =C17*D17 -> 19.2
B18: Amaro Noix (BARKONSULT) | D18: 21.8 | E18: =C18*D18 -> 0
B19: Amaro Rubarbaro Nardini | D19: 20.3 | E19: =C19*D19 -> 0
B20: Amaro Sfumato (WKY REGAL) | C20: 2.6 | D20: 11.16 | E20: =C20*D20 -> 29.016
B21: Martini Bitter | C21: 0.3 | D21: 12.1 | E21: =C21*D21 -> 3.63
E22: =C22*D22 -> 0
B23: APERITIVOS
B24: Aperitivo Lillet Blanc (ÁLVAREZ) | D24: 10.39 | E24: =C24*D24 -> 0
B25: Aperitivo Lillet blanc (BORDINO) | C25: 2.6 | D25: 8.48 | E25: =C25*D25 -> 22.048
B26: Aperitivo Lillet Rouge (BORDINO) | D26: 8.48 | E26: =C26*D26 -> 0
B27: Aperitivo Lillet Rouge (LAFUENTE) | D27: 10.39 | E27: =C27*D27 -> 0
E28: =C28*D28 -> 0
B29: ARMAGÑAC
B30: Armagñac Cles de ducs V.S.O.P | D30: 15.5 | E30: =C30*D30 -> 0
B31: Armagñac Armin 10 | C31: 0.5 | D31: 34.24 | E31: =C31*D31 -> 17.12
B32: Armagñac Armin 6 | C32: 0.7 | D32: 20.89 | E32: =C32*D32 -> 14.623
B33: Armagñac DARTIGALONGUE RESERVA 2000 | D33: 42.25 | E33: =C33*D33 -> 0
B34: Armin blanco | C34: 0.8 | D34: 18.46 | E34: =C34*D34 -> 14.768
E35: =C35*D35 -> 0
B36: BITTERS
B37: Bitter Angostura (BORDINO) | D37: 9.12 | E37: =C37*D37 -> 0
B38: Bitter Burlesque (LAFUENTE) | D38: 18.44 | E38: =C38*D38 -> 0
B39: Bitter Cardamomo | D39: 12.91 | E39: =C39*D39 -> 0
B40: Bitter de Apio fee brothers | D40: 14.01 | E40: =C40*D40 -> 0
B41: Bitter hellfire habanero | D41: 18.44 | E41: =C41*D41 -> 0
...

Sheet Stock producciones
J1: Devil
B2: Producciones | J2: Rubarbaro | K2: 10 | L2: 700 | M2: ='Productos-precio'!D16 -> 11.16 | N2: =(M2*K2)/L2 -> 0.15942857
J3: Campari | K3: 30 | L3: 1000 | M3: ='Productos-precio'!D135 -> 13.04 | N3: =(M3*K3)/L3 -> 0.3912
B4: Producto en botella | C4: cantidad | E4: Garrafas | F4: Cantidad | J4: Vermouth rojo | K4: 20 | L4: 1000 | M4: ='Productos-precio'!D365 -> 9.22 | N4: =(M4*K4)/L4 -> 0.1844
B5: Licor Pandam | E5: Licor pandam 10L | G5: Garrafa 8L | H5: Equivalencia | J5: Disarono | K5: 10 | L5: 700 | M5: 10.91 | N5: =(M5*K5)/L5 -> 0.15585714
B6: Devil | E6: Devil 4L | G6: 1 | H6: 8000 | J6: Cocktails x 1 | K6: =SUM(K2:K5) -> 70 | N6: =SUM(N2:N5) -> 0.89088571
B7: Orange lovo licor | E7: Orange lovo licor 2L | G7: 0.9 | H7: 7200 | J7: Cocktails x botella | K7: =L7/K6 -> 10 | L7: 700 | N7: =N6*K7 -> 8.9088571
B8: Sirope simple | E8: Sirope simple 8L | G8: 0.8 | H8: 6400 | J8: Botellas de 700 | K8: =C6 -> 0 | L8: 700 | N8: =K8*N7 -> 0
B9: Mix ron | E9: Mix ron 4L | G9: 0.7 | H9: 5600 | J9: Garrafa 8L | K9: =L9/K6 -> 0 | L9: =F6 -> 0 | N9: =N6*K9 -> 0
B10: Mix amaros 0,5L | E10: Mix amaros 2L | G10: 0.6 | H10: 4800 | O10: =SUM(N8:N9) -> 0
B11: Sirope eneldo | E11: Sirope eneldo 4L | G11: 0.5 | H11: 4000 | J11: Orange lovo liquor
B12: Jupe banane (en platano) | E12: Jupe banane 5L | G12: 0.4 | H12: 3200 | J12: Cointreau | K12: 300 | L12: 700 | M12: ='Productos-precio'!D149 -> 13.41 | N12: =(M12*K12)/L12 -> 5.7471429
B13: Samurai | E13: Samurai 5L | G13: 0.3 | H13: 2400 | J13: Suau | K13: 200 | L13: 700 | M13: ='Productos-precio'!D201 -> 18.1 | N13: =(M13*K13)/L13 -> 5.1714286
B14: Leona | E14: Leona 8L | G14: 0.2 | H14: 1600 | J14: Dry curaçao Marie Brizard | K14: 500 | L14: 700 | M14: ='Productos-precio'!D177 -> 7.41 | N14: =(M14*K14)/L14 -> 5.2928571
B15: Solucion citrica | E15: Solucion citrica 8L | G15: 0.1 | H15: 800 | J15: Orange bitter | K15: 5 | L15: 200 | M15: ='Productos-precio'!D37 -> 8.68 | N15: =(M15*K15)/L15 -> 0.217
B16: Bubi | E16: Bubi 5L | J16: Cocktails x1 | K16: =SUM(K12:K15) -> 1005 | N16: =SUM(N12:N15) -> 16.428429
B17: Solucion salina 1L | J17: Cocktails x botella | K17: =L17/K16 -> 0.69651741 | L17: 700 | N17: =N16*K17 -> 11.442687
B18: Manabi | E18: Manabi 5L | G18: Garrafa 2L | H18: Equivalencia | J18: Botellas de 700 | K18: =C9 -> 0 | L18: 700 | N18: =N17*K18 -> 0
B19: Mix licores café | E19: Mix liores café 2L | G19: 1 | H19: 2000 | J19: Botella 2L | K19: =L19/K16 -> 0 | L19: =F7 -> 0 | N19: =N16*K19 -> 0
B20: Mix criollo | E20: Mix Criollo 2L | G20: 0.9 | H20: 1800
B21: Tintura algarroba 0,5L | G21: 0.8 | H21: 1600 | O21: =SUM(N18:N19) -> 0
B22: Licor Salmon & Eneldo | E22: Licor Salmon & Elendo 5L | G22: 0.7 | H22: 1400
B23: Maori | E23: Maori 5L | G23: 0.6 | H23: 1200 | J23: Licor Pandam
B24: Tintura de Contriti | E24: Licor Lima Kaffir 5L | G24: 0.5 | H24: 1000 | J24: Licor pandam | K24: 50 | L24: 1200 | M24: =Producciones!F96 -> 12.757606 | N24: =(M24*K24)/L24 -> 0.53156692
E25: Licor Lemon Grass 5L | G25: 0.4 | H25: 800 | J25: Cocktails x1 | K25: 50 | N25: =SUM(N24:N24) -> 0.53156692
E26: Té Josephine Sin 2L | G26: 0.3 | H26: 600 | J26: Cocktails x botella | K26: =L26/K25 -> 14 | L26: 700 | N26: =N25*K26 -> 7.4419369
B27: Josephine sin | E27: Mix josephine sin 2L | G27: 0.2 | H27: 400 | J27: Botellas de 700 | K27: =C5 -> 0 | L27: 700 | N27: =N26*K27 -> 0
B28: Café | E28: Café 2L | G28: 0.1 | H28: 200 | J28: Garrafa | K28: =L28/K25 -> 0 | L28: =F5 -> 0 | N28: =N25*K28 -> 0
B29: Masai | E29: Masai 5L
B30: Indio Navajo | E30: Indio Navajo 5L | O30: =SUM(N27:N28) -> 0
B31: Mix champs sin alcohol | E31: Mix Champs Sin 2L | G31: Garrafa 5L
B32: Sirope maraschino 0,7L | E32: Sirope maraschino 2L | G32: 1 | H32: 5000 | J32: Sirope Simple
B33: Hellfire casero 0,7L | G33: 0.9 | H33: 4500 | J33: Cocktails x 1 | K33: 25 | L33: 1500 | M33: =Producciones!F130 -> 2.6166667 | N33: =(M33*K33)/L33 -> 0.043611111
B34: Sami | E34: Sami 5L | G34: 0.8 | H34: 4000 | J34: Cocktails x botella | K34: =L34/K33 -> 28 | L34: 700 | N34: =N33*K34 -> 1.2211111
B35: Serpiente | E35: Serpiente 5L | G35: 0.7 | H35: 3500
B36: Tortuga | E36: Tortuga 5L | G36: 0.6 | H36: 3000 | J36: Botellas de 700 | K36: =C8 -> 0 | L36: 700 | N36: =N33*K36 -> 0
B37: Mowgli | E37: Mowgli 5L | G37: 0.5 | H37: 2500 | J37: Garrafa | K37: =L37/K33 -> 0 | L37: =F8 -> 0 | N37: =N33*K37 -> 0
B38: Reno | E38: Reno 5L | G38: 0.4 | H38: 2000 | O38: =SUM(N36:N37) -> 0
B39: Caballo | E39: Caballo 5L | G39: 0.3 | H39: 1500 | J39: Mix ron
B40: Sapo Cururu | E40: Sapo Cururu 5L | G40: 0.2 | H40: 1000 | J40: Ron Brugal Extra Viejo | K40: 400 | L40: 700 | M40: 14 | N40: =M40*K40/L40 -> 8
...

Sheet Cristaleria
B1: VASOS | C1: DJ | D1: BARRA CAZA | E1: BARRA CUEVA | F1: SALA | G1: TOTAL | H1: PRECIO | I1: VALOR TOTAL
B3: Bananas | G3: =SUM(C3:F3) -> 0 | H3: 5 | I3: =G3*H3 -> 0
B4: Bandeja Dorada | C4: 6 | G4: =SUM(C4:F4) -> 6 | I4: =G4*H4 -> 0
B5: Chupito alto | G5: =SUM(C5:F5) -> 0 | I5: =G5*H5 -> 0
B6: Chupito bienvenida | C6: 6 | G6: =SUM(C6:F6) -> 6 | H6: 2.34 | I6: =G6*H6 -> 14.04
B7: Chupito shuffle | C7: 6 | G7: =SUM(C7:F7) -> 6 | H7: 1.5 | I7: =G7*H7 -> 9
B8: Chupitos | D8: 25 | E8: 23 | G8: =SUM(C8:F8) -> 48 | H8: 1.04 | I8: =G8*H8 -> 49.92
B9: Copa Belle epoque | G9: =SUM(C9:F9) -> 0 | H9: 15 | I9: =G9*H9 -> 0
B10: Copa pony Savage | G10: =SUM(C10:F10) -> 0 | H10: 4.4 | I10: =G10*H10 -> 0
B11: Copas de Vino | C11: 18 | D11: 17 | E11: 4 | G11: =SUM(C11:F11) -> 39 | H11: 1.9 | I11: =G11*H11 -> 74.1
B12: Coupette Expreso | C12: 11 | G12: =SUM(C12:F12) -> 11 | H12: 3.93 | I12: =G12*H12 -> 43.23
B13: Coupette savage | C13: 6 | E13: 1 | G13: =SUM(C13:F13) -> 7 | H13: 3.92 | I13: =G13*H13 -> 27.44
B14: Cuenco azul crital | G14: =SUM(C14:F14) -> 0
B15: Cuenco Dorado | C15: 8 | G15: =SUM(C15:F15) -> 8 | I15: =G15*H15 -> 0
B16: Cuenco Dorado mini | G16: =SUM(C16:F16) -> 0 | I16: =G16*H16 -> 0
B17: Cuenco Okami | G17: =SUM(C17:F17) -> 0 | I17: =G17*H17 -> 0
B18: Cuenco Tibetano | C18: 6 | G18: =SUM(C18:F18) -> 6 | I18: =G18*H18 -> 0
B19: Highball Geneve (combinado) | C19: 84 | G19: =SUM(C19:F19) -> 84 | H19: 2.69 | I19: =G19*H19 -> 225.96
B20: Highball Italesse (Highball RHR) | G20: =SUM(C20:F20) -> 0 | H20: 2.79 | I20: =G20*H20 -> 0
B21: Highball Levitas | C21: 12 | D21: 6 | E21: 1 | G21: =SUM(C21:F21) -> 19 | H21: 4.99 | I21: =G21*H21 -> 94.81
B22: Highball Levitas mini | D22: 11 | G22: =SUM(C22:F22) -> 11 | H22: 6.2 | I22: =G22*H22 -> 68.2
B23: Highball Tubo Aleman | C23: 19 | D23: 9 | G23: =SUM(C23:F23) -> 28 | H23: 0.8 | I23: =G23*H23 -> 22.4
B24: Highball Tubo Aleman Mini | C24: 36 | E24: 2 | G24: =SUM(C24:F24) -> 38 | H24: 0.78 | I24: =G24*H24 -> 29.64
B25: Highball Aleman corto | D25: 94 | G25: =SUM(C25:F25) -> 94 | I25: =G25*H25 -> 0
B26: Highball Savage | D26: 12 | E26: 7 | G26: =SUM(C26:F26) -> 19 | H26: 4.21 | I26: =G26*H26 -> 79.99
B27: Highball Combinado jerte | C27: 5 | E27: 2 | G27: =SUM(C27:F27) -> 7 | H27: 1.5 | I27: =G27*H27 -> 10.5
B28: Josephine | C28: 4 | G28: =SUM(C28:F28) -> 4 | I28: =G28*H28 -> 0
B29: Lovo | C29: 4 | G29: =SUM(C29:F29) -> 4 | I29: =G29*H29 -> 0
B30: Old fashioned antiguo | C30: 18 | D30: 20 | E30: 48 | G30: =SUM(C30:F30) -> 86 | I30: =G30*H30 -> 0
B31: Old Fashioned chicago cueva | C31: 39 | G31: =SUM(C31:F31) -> 39 | H31: 1.59 | I31: =G31*H31 -> 62.01
B32: Old fashioned Savage | C32: 17 | D32: 12 | E32: 3 | G32: =SUM(C32:F32) -> 32 | H32: 5.33 | I32: =G32*H32 -> 170.56
B33: Pinzas | C33: 3 | D33: 28 | G33: =SUM(C33:F33) -> 31 | I33: =G33*H33 -> 0
B34: Piñas | D34: 5 | G34: =SUM(C34:F34) -> 5 | H34: 60 | I34: =G34*H34 -> 300
B35: Probetas | G35: =SUM(C35:F35) -> 0 | H35: 0.6 | I35: =G35*H35 -> 0
B36: Recipiente nordico | D36: 5 | G36: =SUM(C36:F36) -> 5 | I36: =G36*H36 -> 0
B37: Tabla Madera | G37: =SUM(C37:F37) -> 0 | I37: =G37*H37 -> 0
B38: Tumbler Nude | G38: =SUM(C38:F38) -> 0 | H38: 5.08 | I38: =G38*H38 -> 0
B39: Vasos de Agua Averna Pure | G39: =SUM(C39:F39) -> 0 | H39: 5.93 | I39: =G39*H39 -> 0
B40: Vasos Tam Tam | C40: 10 | G40: =SUM(C40:F40) -> 10 | I40: =G40*H40 -> 0
B41: VASOS MOSCOW MULE | I41: =SUM(I3:I40) -> 1281.8

Sheet Producciones
B1: Producciones
B4: CITRUS SOUL
C5: ml/gr | D5: Unidad | E5: Precio | F5: Precio coste
B6: Agua | C6: 1000 | D6: 1000 | E6: 0 | F6: =(C6*E6)/D6 -> 0
B7: Ácido citrico | C7: 20 | D7: 1000 | E7: 1.82 | F7: =(C7*E7)/D7 -> 0.0364
B8: Ácido tartarico | C8: 10 | D8: 1000 | E8: 3.42 | F8: =(C8*E8)/D8 -> 0.0342
B9: Ácido malico | C9: 5 | D9: 250 | E9: 5.6 | F9: =(C9*E9)/D9 -> 0.112
B10: Ácido ascorbico | C10: 5 | D10: 1000 | E10: 3.9 | F10: =(C10*E10)/D10 -> 0.0195
B11: Sal | C11: 2 | D11: 1000 | E11: 0.5 | F11: =(C11*E11)/D11 -> 0.001
B12: Azucar | C12: 4 | D12: 1000 | E12: 1.13 | F12: =(C12*E12)/D12 -> 0.00452
B13: MDO | C13: 4 | D13: 60 | E13: 14.5 | F13: =(C13*E13)/D13 -> 0.96666667
E14: Coste total | F14: =F6+F7+F8+F9+F10+F11+F12+F13 -> 1.1742867
E15: Coste + IVA | F15: =(F14*21%)+F14 -> 1.4208869
B16: Prodecimiento | C16: Añadir todos los ingrediente en el robot de cocina a 35Cº, Vel 4, 5min, embotellar y etiquetar
B20: LICOR DE CACHUETE
C21: ml/gr | D21: Unidad | E21: Precio | F21: Precio coste
B22: Vodka Whitlley Neill | C22: 900 | D22: 700 | E22: 7 | F22: 7
B23: Cacahuete | C23: 160 | D23: 1000 | E23: 5 | F23: =(C23*E23)/D23 -> 0.8
B24: Sirope Simple | C24: 300 | D24: 1000 | E24: 1.76 | F24: =(C24*E24)/D24 -> 0.528
E26: Coste total | F26: =F22+F23+F24+F25 -> 8.328
E27: Coste + IVA | F27: =(F26*21%)+F26 -> 10.07688
B28: Prodecimiento | C28: en la misma bolsa u otra machacar un poco el cacahuete, agregar a la bolsa al vacio con el vodka y el sirope simpre. Cocinar en la roner durante 1h a 55ºC, congelar durante 45min y filtrar en filtro de tela.
B31: TÉ OLONG MILKY
C32: ml/gr | D32: Unidad | E32: Precio | F32: Precio coste
B33: Agua | C33: 1000 | D33: 1000 | E33: 0 | F33: =(C33*E33)/D33 -> 0
B34: Té Olong | C34: 10 | D34: 50 | E34: 3.5 | F34: =(C34*E34)/D34 -> 0.7
B35: Sirope Simple | C35: 100 | D35: 1000 | E35: 1.76 | F35: =(C35*E35)/D35 -> 0.176
E36: Coste total | F36: =SUM(F33:F35) -> 0.876
E37: Coste + IVA | F37: =(F36*21%)+F36 -> 1.05996
B38: Prodecimiento | C38: Añadir el té, agua en una bolsa al vacio. Meter en la roner a 70ºC durante 30min
B42: LICOR TÉ CHAI
C43: ml/gr | D43: Unidad | E43: Precio | F43: Precio Coste
B44: Vodka Whitley Neill | C44: 1200 | D44: 700 | E44: 7 | F44: =(C44*E44)/D44 -> 12
B45: Té Chai | C45: 12 | D45: 40 | E45: 4 | F45: =(C45*E45)/D45 -> 1.2
B46: Sirope simple | C46: 400 | D46: 1000 | E46: 2 | F46: =(C46*E46)/D46 -> 0.8
E48: Coste total | F48: =SUM(F44:F46) -> 14
E49: Coste + IVA | F49: =(F48*21%)+F48 -> 16.94
B50: Prodecimiento | C50: Envasar al vacio los ingredientes, ponerla en la roner durante 30 minutos a 70ºC, filtrar por superbag, embitellar y etiquetar
B53: CORDIAL TÉ EARL GREY
C54: ml/gr | D54: Unidad | E54: Precio | F54: Precio Coste
...
